<mujoco>
  <worldbody>
    <!-- Mobile Base -->
    <body name="base" pos="0 0 0.1">
      <joint name="base_joint" type="slide" axis="1 0 0" range="-10 10"/>
      <geom name="base_geom" type="box" size="0.5 0.5 0.1" rgba="0.5 0.5 0.5 1"/>
      
      <!-- Robotic Arm -->
      <body name="link1" pos="0 0 0.2">
        <joint name="joint1" type="hinge" axis="0 0 1" range="-90 90"/>
        <geom name="link1_geom" type="cylinder" size="0.1 0.2" rgba="0 0 1 1"/>
        
        <body name="link2" pos="0 0 0.4">
          <joint name="joint2" type="hinge" axis="0 1 0" range="-90 90"/>
          <geom name="link2_geom" type="cylinder" size="0.1 0.2" rgba="0 1 0 1"/>
          
          <!-- End Effector -->
          <body name="end_effector" pos="0 0 0.2">
            <geom name="ee_geom" type="box" size="0.1 0.1 0.1" rgba="1 0 0 1"/>
          </body>
        </body>
      </body>
      
      <!-- Storage Holder -->
      <body name="storage" pos="0.5 0 0.1">
        <geom name="storage_geom" type="box" size="0.3 0.3 0.2" rgba="0.8 0.8 0 1"/>
      </body>
    </body>
  </worldbody>
  
  <actuator>
    <motor name="base_motor" joint="base_joint" gear="1"/>
    <motor name="joint1_motor" joint="joint1" gear="1"/>
    <motor name="joint2_motor" joint="joint2" gear="1"/>
  </actuator>
</mujoco>